<?xml version="1.0" ?>
<!-- =================================================================================== -->
<!-- |    This document was autogenerated by xacro from /smart_grasping_sandbox/src/smart_grasping_sandbox/fh_desc/robots/right_H1_ur5.urdf | -->
<!-- |    EDITING THIS FILE BY HAND IS NOT RECOMMENDED                                 | -->
<!-- =================================================================================== -->
<robot name="smart_grasping_sandbox" xmlns:xacro="http://ros.org/wiki/xacro">

  <!-- Colors -->
  <material name="DarkGrey">
    <color rgba="0.2 0.2 0.2 1.0"/>
  </material>
  <material name="Grey">
    <color rgba="0.4 0.4 0.4 1.0"/>
  </material>
  <material name="Orange">
    <color rgba="1.0 0.423529411765 0.0392156862745 1.0"/>
  </material>
  <material name="Blue">
    <color rgba="0 0.1 1.0 1.0"/>
  </material>
  <material name="LightGrey">
    <color rgba="0.7 0.7 0.7 1.0"/>
  </material>
  <material name="Red">
    <color rgba="0.9 0 0.2 1.0"/>
  </material>
  <material name="Green">
    <color rgba="0 0.9 0.5 1.0"/>
  </material>
  <material name="Yellow">
    <color rgba="0.7 0.7 0 1.0"/>
  </material>
  <material name="LightBlue">
    <color rgba="0. 0.3 1.0 1.0"/>
  </material>
  <material name="Black">
    <color rgba="0.05 0.05 0.05 1.0"/>
  </material>
  <material name="White">
    <color rgba="1.0 1.0 1.0 1.0" />
  </material>
  <material name="TacTipWhite">
   <color rgba="0.8 0.8 0.8 1.0"/>
 </material>
 <material name="TransparentRed">
   <color rgba="0.9 0 0.2 0.5"/>
 </material>

<!-- ====================== Shadow Modular Grasper ====================== -->

<!-- connect hand to world -->
<link name="world"/>

<link name="SMG_base_link">
  <inertial>
    <origin rpy="0 0 0" xyz="-8.6116E-06 -0.0058125 0.028294"/>
    <mass value="0.07527"/>
    <inertia ixx="0.00014442" ixy="1.2033E-08" ixz="-5.9646E-10" iyy="0.00014979" iyz="-1.0288E-05" izz="5.2943E-05"/>
  </inertial>

  <visual>
    <origin rpy="0 0 0" xyz="0 0 0"/>
    <geometry>
      <mesh filename="hand/palm_link_simple.dae"/>
    </geometry>
    <material name="DarkGrey"/>
  </visual>

  <collision>
    <origin rpy="0 0 0" xyz="0 0 0"/>
    <geometry>
      <mesh filename="hand/palm_link_simple.dae"/>
    </geometry>
  </collision>
</link>

<joint name="SMG_base_joint" type="fixed">
  <origin rpy="0 0 0" xyz="0 0 0"/>
  <parent link="world"/>
  <child link="SMG_wrist_attach"/>
</joint>

<link name="SMG_wrist_attach">
  <inertial>
    <mass value="0.1879"/>
    <origin rpy="0 0 0" xyz="0.0 0.0 0.0"/>
    <inertia ixx="1.0" ixy="0.0" ixz="0.0" iyy="1.0" iyz="0.0" izz="1.0"/>
  </inertial>
</link>

<joint name="SMG_base_link_wrist_attach" type="fixed">
  <origin rpy="0 0 0" xyz="0 0 -0.0005"/>
  <child link="SMG_base_link"/>
  <parent link="SMG_wrist_attach"/>
</joint>


  <!-- ============= SMG Body =============== -->
  <link name="SMG_insert_F1">
    <inertial>
      <mass value="0.1879"/>
      <origin rpy="0 0 0" xyz="0.0 0.0 0.0"/>
      <inertia ixx="1.0" ixy="0.0" ixz="0.0" iyy="1.0" iyz="0.0" izz="1.0"/>
    </inertial>
  </link>

  <joint name="SMG_dummy_joint_1" type="fixed">
    <origin rpy="0 0 2.3562" xyz="-0.045 -0.025981 0"/>
    <axis xyz="0 -1 0"/>
    <parent link="SMG_base_link"/>
    <child link="SMG_insert_F1"/>
  </joint>

  <link name="SMG_insert_F2">
    <inertial>
      <mass value="0.1879"/>
      <origin rpy="0 0 0" xyz="0.0 0.0 0.0"/>
      <inertia ixx="1.0" ixy="0.0" ixz="0.0" iyy="1.0" iyz="0.0" izz="1.0"/>
    </inertial>
  </link>

  <joint name="SMG_dummy_joint_2" type="fixed">
    <origin rpy="0 0 0" xyz="0 0.029019 0"/>
    <axis xyz="0 -1 0"/>
    <parent link="SMG_base_link"/>
    <child link="SMG_insert_F2"/>
  </joint>

  <link name="SMG_insert_F3">
    <inertial>
      <mass value="0.1879"/>
      <origin rpy="0 0 0" xyz="0.0 0.0 0.0"/>
      <inertia ixx="1.0" ixy="0.0" ixz="0.0" iyy="1.0" iyz="0.0" izz="1.0"/>
    </inertial>
  </link>

  <joint name="SMG_dummy_joint_3" type="fixed">
    <origin rpy="0 0 -2.3562" xyz="0.045 -0.025981 0"/>
    <axis xyz="0 -1 0"/>
    <parent link="SMG_base_link"/>
    <child link="SMG_insert_F3"/>
  </joint>


  <!-- ============= Finger 1 =============== -->
  <link name="SMG_F1_palm_link">
    <inertial>
      <origin rpy="0 0 0" xyz="-0.00681802120880393 -0.00947020456878004 0.067587996682422"/>
      <mass value="0.0341482312344481"/>
      <inertia ixx="2.79747833772125E-05" ixy="-5.50900644725373E-08" ixz="-2.82072424927723E-07" iyy="2.67800858812928E-05" iyz="3.1953125069394E-06" izz="9.86122271726361E-06"/>
    </inertial>

    <visual>
      <origin rpy="0 0 0" xyz="0 0 0"/>
      <geometry>
        <mesh filename="hand/finger_palm_link.dae"/>
      </geometry>
      <material name="DarkGrey"/>
    </visual>

    <collision>
      <origin rpy="0 0 0" xyz="0 0 0"/>
      <geometry>
        <mesh filename="hand/finger_palm_link.dae"/>
      </geometry>
    </collision>
  </link>

  <link name="SMG_F1_base_link">
    <inertial>
      <origin rpy="0 0 0" xyz="-0.000142856770000038 0.0265691681336443 0.0538751581621436"/>
      <mass value="0.174652229503358"/>
      <inertia ixx="0.000298372741514267" ixy="-5.05751882577435E-07" ixz="1.94982779411417E-07" iyy="0.000299629589232877" iyz="2.79565205733806E-05" izz="0.000134889645145365"/>
    </inertial>

    <visual>
      <origin rpy="0 0 0" xyz="0 0 0"/>
      <geometry>
        <mesh filename="hand/finger_base_link_simple.dae"/>
      </geometry>
      <material name="DarkGrey"/>
    </visual>

    <collision>
      <origin rpy="0 0 0" xyz="0 0 0"/>
      <geometry>
        <mesh filename="hand/finger_base_link_simple.dae"/>
      </geometry>
    </collision>
  </link>

  <link name="SMG_F1_link_1">
    <inertial>
      <origin rpy="0 0 0" xyz="-0.000141876508729455 -0.00135409566494088 0.0277606215980989"/>
      <mass value="0.0827759744227546"/>
      <inertia ixx="4.61070151157777E-05" ixy="7.47741111557837E-08" ixz="-2.25165057702697E-07" iyy="5.27678327317508E-05" iyz="-3.64603343546298E-07" izz="2.89599551320955E-05"/>
    </inertial>

    <visual>
      <origin rpy="0 0 0" xyz="0 0 0"/>
      <geometry>
        <mesh filename="hand/finger_prox_link_simple.dae"/>
      </geometry>
      <material name="LightGrey"/>
    </visual>

    <collision>
      <origin rpy="0 0 0" xyz="0 0 0"/>
      <geometry>
        <mesh filename="hand/finger_prox_link_simple.dae"/>
      </geometry>
    </collision>
  </link>

  <link name="SMG_F1_link_2">
    <inertial>
      <origin rpy="0 0 0" xyz="0.000506812071918918 -0.00091292934992606 0.0156620851768385"/>
      <mass value="0.0270049614151599"/>
      <inertia ixx="1.06942730265546E-05" ixy="-7.1810089794211E-09" ixz="-3.49957211410822E-07" iyy="1.05772889540593E-05" iyz="-8.38595987731518E-07" izz="3.27173446995846E-06"/>
    </inertial>

    <visual>
      <origin rpy="0 0 0" xyz="0 0 0"/>
      <geometry>
        <mesh filename="tip/dist_hand_mount.obj"/>
      </geometry>
      <material name="DarkGrey"/>
    </visual>

    <collision>
      <origin rpy="0 0 0" xyz="0 0 0"/>
      <geometry>
        <mesh filename="tip/dist_hand_mount.obj"/>
      </geometry>
    </collision>
  </link>

  <joint name="SMG_F1_palm" type="fixed">
    <origin rpy="0 0 0" xyz="0 0 0"/>
    <parent link="SMG_insert_F1"/>
    <child link="SMG_F1_palm_link"/>
  </joint>

  <joint name="SMG_F1J1" type="revolute">
    <origin rpy="-8.8818E-16 -1.0061E-16 0.022402" xyz="0 0 0.00016528"/>
    <axis xyz="0 0 1"/>
    <parent link="SMG_F1_palm_link"/>
    <child link="SMG_F1_base_link"/>
    <limit effort="50" lower="-0.785398163397" upper="0.785398163397" velocity="1.0"/>
    <!-- <dynamics damping="0.5" friction="0.0"/> -->
  </joint>

  <joint name="SMG_F1J2" type="revolute">
    <origin rpy="0.070695 6.9389E-16 2.0947E-16" xyz="0 0.035 0.11683"/>
    <axis xyz="1 0 0"/>
    <parent link="SMG_F1_base_link"/>
    <child link="SMG_F1_link_1"/>
    <limit effort="50" lower="-1.3962634016" upper="1.0471975512" velocity="1.0"/>
    <!-- <dynamics damping="0.5" friction="0.0"/> -->
  </joint>

  <joint name="SMG_F1J3" type="revolute">
    <origin rpy="-0.0068649 1.7347E-18 1.6176E-16" xyz="0 0 0.06"/>
    <axis xyz="1 0 0"/>
    <parent link="SMG_F1_link_1"/>
    <child link="SMG_F1_link_2"/>
    <limit effort="50" lower="-1.0471975512" upper="1.57079632679" velocity="1.0"/>
    <!-- <dynamics damping="0.5" friction="0.0"/> -->
  </joint>

  <link name="SMG_F1_tactip_body">
    <inertial>
      <origin rpy="0 0 0" xyz="-0.000925580990320645 -0.00495543398528436 0.0355865585792753"/>
      <mass value="0.01"/>
      <inertia ixx="1E-06" ixy="0" ixz="0" iyy="1E-06" iyz="0" izz="1E-06"/>
    </inertial>

    <visual>
      <origin rpy="0 0 0" xyz="0 0 0"/>
      <geometry>
        <mesh filename="tip/smg_tactip_body.obj"/>
      </geometry>
      <material name="TacTipWhite"/>
    </visual>

    <collision>
      <origin rpy="0 0 0" xyz="0 0 0"/>
      <geometry>
        <mesh filename="tip/smg_tactip_body.obj"/>
      </geometry>
    </collision>
  </link>

  <joint name="SMG_F1_tactip_body_joint" type="fixed">
    <parent link="SMG_F1_link_2"/>
    <child link="SMG_F1_tactip_body"/>
  </joint>

  <link name="SMG_F1_tactip_tip">
    <inertial>
      <origin rpy="0 0 0" xyz="-0.000925580990320645 -0.00495543398528436 0.0355865585792753"/>
      <mass value="0.01"/>
      <inertia ixx="1E-06" ixy="0" ixz="0" iyy="1E-06" iyz="0" izz="1E-06"/>
    </inertial>

    <visual>
      <origin rpy="0 0 0" xyz="0 0 0"/>
      <geometry>
        <mesh filename="tip/smg_tactip_skin.obj"/>
      </geometry>
      <material name="Black"/>
    </visual>

    <collision>
      <origin rpy="0 0 0" xyz="0 0 0"/>
      <geometry>
        <mesh filename="tip/smg_tactip_core.obj"/>
      </geometry>
    </collision>
  </link>

  <joint name="SMG_F1_tactip_tip_joint" type="fixed">
    <parent link="SMG_F1_tactip_body"/>
    <child link="SMG_F1_tactip_tip"/>
  </joint>

  <!-- TCP -->
  <link name="F1_tcp_link">
    <visual>
      <origin rpy="0 0 0" xyz="0 0 0"/>
      <geometry>
        <sphere radius="0.005"/>
      </geometry>
       <material name="TransparentRed"/>
    </visual>
    <inertial>
      <mass value="0.0"/>
      <origin rpy="0.0 0.0 3.14" xyz="0.0 0.0 0.0"/>
      <inertia ixx="1.0" ixy="0.0" ixz="0.0" iyy="1.0" iyz="0.0" izz="1.0"/>
    </inertial>
  </link>

  <joint name="F1_tcp_joint" type="fixed">
    <parent link="SMG_F1_tactip_body"/>
    <child link="F1_tcp_link"/>
    <origin rpy="0 0 0" xyz="0.0 -0.0175 0.035"/>
  </joint>


  <!-- ============= Finger 2 =============== -->
  <link name="SMG_F2_palm_link">
    <inertial>
      <origin rpy="0 0 0" xyz="-0.00681802120880393 -0.00947020456878004 0.067587996682422"/>
      <mass value="0.0341482312344481"/>
      <inertia ixx="2.79747833772125E-05" ixy="-5.50900644725373E-08" ixz="-2.82072424927723E-07" iyy="2.67800858812928E-05" iyz="3.1953125069394E-06" izz="9.86122271726361E-06"/>
    </inertial>

    <visual>
      <origin rpy="0 0 0" xyz="0 0 0"/>
      <geometry>
        <mesh filename="hand/finger_palm_link.dae"/>
      </geometry>
      <material name="DarkGrey"/>
    </visual>

    <collision>
      <origin rpy="0 0 0" xyz="0 0 0"/>
      <geometry>
        <mesh filename="hand/finger_palm_link.dae"/>
      </geometry>
    </collision>
  </link>

  <link name="SMG_F2_base_link">
    <inertial>
      <origin rpy="0 0 0" xyz="-0.000142856770000038 0.0265691681336443 0.0538751581621436"/>
      <mass value="0.174652229503358"/>
      <inertia ixx="0.000298372741514267" ixy="-5.05751882577435E-07" ixz="1.94982779411417E-07" iyy="0.000299629589232877" iyz="2.79565205733806E-05" izz="0.000134889645145365"/>
    </inertial>

    <visual>
      <origin rpy="0 0 0" xyz="0 0 0"/>
      <geometry>
        <mesh filename="hand/finger_base_link_simple.dae"/>
      </geometry>
      <material name="DarkGrey"/>
    </visual>

    <collision>
      <origin rpy="0 0 0" xyz="0 0 0"/>
      <geometry>
        <mesh filename="hand/finger_base_link_simple.dae"/>
      </geometry>
    </collision>
  </link>


  <link name="SMG_F2_link_1">
    <inertial>
      <origin rpy="0 0 0" xyz="-0.000141876508729455 -0.00135409566494088 0.0277606215980989"/>
      <mass value="0.0827759744227546"/>
      <inertia ixx="4.61070151157777E-05" ixy="7.47741111557837E-08" ixz="-2.25165057702697E-07" iyy="5.27678327317508E-05" iyz="-3.64603343546298E-07" izz="2.89599551320955E-05"/>
    </inertial>

    <visual>
      <origin rpy="0 0 0" xyz="0 0 0"/>
      <geometry>
        <mesh filename="hand/finger_prox_link_simple.dae"/>
      </geometry>
      <material name="LightGrey"/>
    </visual>

    <collision>
      <origin rpy="0 0 0" xyz="0 0 0"/>
      <geometry>
        <mesh filename="hand/finger_prox_link_simple.dae"/>
      </geometry>
    </collision>
  </link>


  <link name="SMG_F2_link_2">
    <inertial>
      <origin rpy="0 0 0" xyz="0.000506812071918918 -0.00091292934992606 0.0156620851768385"/>
      <mass value="0.0270049614151599"/>
      <inertia ixx="1.06942730265546E-05" ixy="-7.1810089794211E-09" ixz="-3.49957211410822E-07" iyy="1.05772889540593E-05" iyz="-8.38595987731518E-07" izz="3.27173446995846E-06"/>
    </inertial>

    <visual>
      <origin rpy="0 0 0" xyz="0 0 0"/>
      <geometry>
        <mesh filename="tip/dist_hand_mount.obj"/>
      </geometry>
      <material name="DarkGrey"/>
    </visual>

    <collision>
      <origin rpy="0 0 0" xyz="0 0 0"/>
      <geometry>
        <mesh filename="tip/dist_hand_mount.obj"/>
      </geometry>
    </collision>
  </link>

  <joint name="SMG_F2_palm" type="fixed">
    <origin rpy="0 0 0" xyz="0 0 0"/>
    <parent link="SMG_insert_F2"/>
    <child link="SMG_F2_palm_link"/>
  </joint>

  <joint name="SMG_F2J1" type="revolute">
    <origin rpy="-8.8818E-16 -1.0061E-16 0.022402" xyz="0 0 0.00016528"/>
    <axis xyz="0 0 1"/>
    <parent link="SMG_F2_palm_link"/>
    <child link="SMG_F2_base_link"/>
    <limit effort="30" lower="-0.785398163397" upper="0.785398163397" velocity="1.0"/>
    <!-- <dynamics damping="0.5" friction="0.0"/> -->
  </joint>

  <joint name="SMG_F2J2" type="revolute">
    <origin rpy="0.070695 6.9389E-16 2.0947E-16" xyz="0 0.035 0.11683"/>
    <axis xyz="1 0 0"/>
    <parent link="SMG_F2_base_link"/>
    <child link="SMG_F2_link_1"/>
    <limit effort="30" lower="-1.3962634016" upper="1.0471975512" velocity="1.0"/>
    <!-- <dynamics damping="0.5" friction="0.0"/> -->
  </joint>

  <joint name="SMG_F2J3" type="revolute">
    <origin rpy="-0.0068649 1.7347E-18 1.6176E-16" xyz="0 0 0.06"/>
    <axis xyz="1 0 0"/>
    <parent link="SMG_F2_link_1"/>
    <child link="SMG_F2_link_2"/>
    <limit effort="30" lower="-1.0471975512" upper="1.57079632679" velocity="1.0"/>
    <!-- <dynamics damping="0.5" friction="0.0"/> -->
  </joint>

  <link name="SMG_F2_tactip_body">
    <inertial>
      <origin rpy="0 0 0" xyz="-0.000925580990320645 -0.00495543398528436 0.0355865585792753"/>
      <mass value="0.01"/>
      <inertia ixx="1E-06" ixy="0" ixz="0" iyy="1E-06" iyz="0" izz="1E-06"/>
    </inertial>

    <visual>
      <origin rpy="0 0 0" xyz="0 0 0"/>
      <geometry>
        <mesh filename="tip/smg_tactip_body.obj"/>
      </geometry>
      <material name="TacTipWhite"/>
    </visual>

    <collision>
      <origin rpy="0 0 0" xyz="0 0 0"/>
      <geometry>
        <mesh filename="tip/smg_tactip_body.obj"/>
      </geometry>
    </collision>
  </link>

  <joint name="SMG_F2_tactip_body_joint" type="fixed">
    <parent link="SMG_F2_link_2"/>
    <child link="SMG_F2_tactip_body"/>
  </joint>

  <link name="SMG_F2_tactip_tip">
    <inertial>
      <origin rpy="0 0 0" xyz="-0.000925580990320645 -0.00495543398528436 0.0355865585792753"/>
      <mass value="0.01"/>
      <inertia ixx="1E-06" ixy="0" ixz="0" iyy="1E-06" iyz="0" izz="1E-06"/>
    </inertial>

    <visual>
      <origin rpy="0 0 0" xyz="0 0 0"/>
      <geometry>
        <mesh filename="tip/smg_tactip_skin.obj"/>
      </geometry>
      <material name="Black"/>
    </visual>

    <collision>
      <origin rpy="0 0 0" xyz="0 0 0"/>
      <geometry>
        <mesh filename="tip/smg_tactip_core.obj"/>
      </geometry>
    </collision>
  </link>

  <joint name="SMG_F2_tactip_tip_joint" type="fixed">
    <parent link="SMG_F2_tactip_body"/>
    <child link="SMG_F2_tactip_tip"/>
  </joint>

  <!-- TCP -->
  <link name="F2_tcp_link">
    <visual>
      <origin rpy="0 0 0" xyz="0 0 0"/>
      <geometry>
        <sphere radius="0.005"/>
      </geometry>
       <material name="TransparentRed"/>
    </visual>
    <inertial>
      <mass value="0.0"/>
      <origin rpy="0.0 0.0 3.14" xyz="0.0 0.0 0.0"/>
      <inertia ixx="1.0" ixy="0.0" ixz="0.0" iyy="1.0" iyz="0.0" izz="1.0"/>
    </inertial>
  </link>

  <joint name="F2_tcp_joint" type="fixed">
    <parent link="SMG_F2_tactip_body"/>
    <child link="F2_tcp_link"/>
    <origin rpy="0 0 0" xyz="0.0 -0.0175 0.035"/>
  </joint>

  <!-- ============= Finger 3 =============== -->
  <link name="SMG_F3_palm_link">
    <inertial>
      <origin rpy="0 0 0" xyz="-0.00681802120880393 -0.00947020456878004 0.067587996682422"/>
      <mass value="0.0341482312344481"/>
      <inertia ixx="2.79747833772125E-05" ixy="-5.50900644725373E-08" ixz="-2.82072424927723E-07" iyy="2.67800858812928E-05" iyz="3.1953125069394E-06" izz="9.86122271726361E-06"/>
    </inertial>

    <visual>
      <origin rpy="0 0 0" xyz="0 0 0"/>
      <geometry>
        <mesh filename="hand/finger_palm_link.dae"/>
      </geometry>
      <material name="DarkGrey"/>
    </visual>

    <collision>
      <origin rpy="0 0 0" xyz="0 0 0"/>
      <geometry>
        <mesh filename="hand/finger_palm_link.dae"/>
      </geometry>
    </collision>
  </link>


  <link name="SMG_F3_base_link">
    <inertial>
      <origin rpy="0 0 0" xyz="-0.000142856770000038 0.0265691681336443 0.0538751581621436"/>
      <mass value="0.174652229503358"/>
      <inertia ixx="0.000298372741514267" ixy="-5.05751882577435E-07" ixz="1.94982779411417E-07" iyy="0.000299629589232877" iyz="2.79565205733806E-05" izz="0.000134889645145365"/>
    </inertial>

    <visual>
      <origin rpy="0 0 0" xyz="0 0 0"/>
      <geometry>
        <mesh filename="hand/finger_base_link_simple.dae"/>
      </geometry>
      <material name="DarkGrey"/>
    </visual>

    <collision>
      <origin rpy="0 0 0" xyz="0 0 0"/>
      <geometry>
        <mesh filename="hand/finger_base_link_simple.dae"/>
      </geometry>
    </collision>
  </link>


  <link name="SMG_F3_link_1">
    <inertial>
      <origin rpy="0 0 0" xyz="-0.000141876508729455 -0.00135409566494088 0.0277606215980989"/>
      <mass value="0.0827759744227546"/>
      <inertia ixx="4.61070151157777E-05" ixy="7.47741111557837E-08" ixz="-2.25165057702697E-07" iyy="5.27678327317508E-05" iyz="-3.64603343546298E-07" izz="2.89599551320955E-05"/>
    </inertial>

    <visual>
      <origin rpy="0 0 0" xyz="0 0 0"/>
      <geometry>
        <mesh filename="hand/finger_prox_link_simple.dae"/>
      </geometry>
      <material name="LightGrey"/>
    </visual>

    <collision>
      <origin rpy="0 0 0" xyz="0 0 0"/>
      <geometry>
        <mesh filename="hand/finger_prox_link_simple.dae"/>
      </geometry>
    </collision>
  </link>



  <link name="SMG_F3_link_2">
    <inertial>
      <origin rpy="0 0 0" xyz="0.000506812071918918 -0.00091292934992606 0.0156620851768385"/>
      <mass value="0.0270049614151599"/>
      <inertia ixx="1.06942730265546E-05" ixy="-7.1810089794211E-09" ixz="-3.49957211410822E-07" iyy="1.05772889540593E-05" iyz="-8.38595987731518E-07" izz="3.27173446995846E-06"/>
    </inertial>

    <visual>
      <origin rpy="0 0 0" xyz="0 0 0"/>
      <geometry>
        <mesh filename="tip/dist_hand_mount.obj"/>
      </geometry>
      <material name="DarkGrey"/>
    </visual>

    <collision>
      <origin rpy="0 0 0" xyz="0 0 0"/>
      <geometry>
        <mesh filename="tip/dist_hand_mount.obj"/>
      </geometry>
    </collision>
  </link>


  <joint name="SMG_F3Palm" type="fixed">
    <origin rpy="0 0 0" xyz="0 0 0"/>
    <parent link="SMG_insert_F3"/>
    <child link="SMG_F3_palm_link"/>
  </joint>

  <joint name="SMG_F3J1" type="revolute">
    <origin rpy="-8.8818E-16 -1.0061E-16 0.022402" xyz="0 0 0.00016528"/>
    <axis xyz="0 0 1"/>
    <parent link="SMG_F3_palm_link"/>
    <child link="SMG_F3_base_link"/>
    <limit effort="30" lower="-0.785398163397" upper="0.785398163397" velocity="1.0"/>
    <!-- <dynamics damping="0.5" friction="0.0"/> -->
  </joint>

  <joint name="SMG_F3J2" type="revolute">
    <origin rpy="0.070695 6.9389E-16 2.0947E-16" xyz="0 0.035 0.11683"/>
    <axis xyz="1 0 0"/>
    <parent link="SMG_F3_base_link"/>
    <child link="SMG_F3_link_1"/>
    <limit effort="30" lower="-1.3962634016" upper="1.0471975512" velocity="1.0"/>
    <!-- <dynamics damping="0.5" friction="0.0"/> -->
  </joint>

  <joint name="SMG_F3J3" type="revolute">
    <origin rpy="-0.0068649 1.7347E-18 1.6176E-16" xyz="0 0 0.06"/>
    <axis xyz="1 0 0"/>
    <parent link="SMG_F3_link_1"/>
    <child link="SMG_F3_link_2"/>
    <limit effort="30" lower="-1.0471975512" upper="1.57079632679" velocity="1.0"/>
    <!-- <dynamics damping="0.5" friction="0.0"/> -->
  </joint>

  <link name="SMG_F3_tactip_body">
    <inertial>
      <origin rpy="0 0 0" xyz="-0.000925580990320645 -0.00495543398528436 0.0355865585792753"/>
      <mass value="0.01"/>
      <inertia ixx="1E-06" ixy="0" ixz="0" iyy="1E-06" iyz="0" izz="1E-06"/>
    </inertial>

    <visual>
      <origin rpy="0 0 0" xyz="0 0 0"/>
      <geometry>
        <mesh filename="tip/smg_tactip_body.obj"/>
      </geometry>
      <material name="TacTipWhite"/>
    </visual>

    <collision>
      <origin rpy="0 0 0" xyz="0 0 0"/>
      <geometry>
        <mesh filename="tip/smg_tactip_body.obj"/>
      </geometry>
    </collision>
  </link>

  <joint name="SMG_F3_tactip_body_joint" type="fixed">
    <parent link="SMG_F3_link_2"/>
    <child link="SMG_F3_tactip_body"/>
  </joint>

  <link name="SMG_F3_tactip_tip">
    <inertial>
      <origin rpy="0 0 0" xyz="-0.000925580990320645 -0.00495543398528436 0.0355865585792753"/>
      <mass value="0.01"/>
      <inertia ixx="1E-06" ixy="0" ixz="0" iyy="1E-06" iyz="0" izz="1E-06"/>
    </inertial>

    <visual>
      <origin rpy="0 0 0" xyz="0 0 0"/>
      <geometry>
        <mesh filename="tip/smg_tactip_skin.obj"/>
      </geometry>
      <material name="Black"/>
    </visual>

    <collision>
      <origin rpy="0 0 0" xyz="0 0 0"/>
      <geometry>
        <mesh filename="tip/smg_tactip_core.obj"/>
      </geometry>
    </collision>
  </link>

  <joint name="SMG_F3_tactip_tip_joint" type="fixed">
    <parent link="SMG_F3_tactip_body"/>
    <child link="SMG_F3_tactip_tip"/>
  </joint>

  <!-- TCP -->
  <link name="F3_tcp_link">
    <visual>
      <origin rpy="0 0 0" xyz="0 0 0"/>
      <geometry>
        <sphere radius="0.005"/>
      </geometry>
       <material name="TransparentRed"/>
    </visual>
    <inertial>
      <mass value="0.0"/>
      <origin rpy="0.0 0.0 3.14" xyz="0.0 0.0 0.0"/>
      <inertia ixx="1.0" ixy="0.0" ixz="0.0" iyy="1.0" iyz="0.0" izz="1.0"/>
    </inertial>
  </link>

  <joint name="F3_tcp_joint" type="fixed">
    <parent link="SMG_F3_tactip_body"/>
    <child link="F3_tcp_link"/>
    <origin rpy="0 0 0" xyz="0.0 -0.0175 0.035"/>
  </joint>

</robot>
